<?xml version="1.0"?>
<!-- =================================================================================== -->
<!-- |    This document was autogenerated by xacro from
/home/fjw/catkin_dtsystem/src/plane_part/urdf/plane_part.urdf.xacro | -->
<!-- |    EDITING THIS FILE BY HAND IS NOT RECOMMENDED                                 | -->
<!-- =================================================================================== -->
<!-- This URDF was automatically created by SolidWorks to URDF Exporter! Originally created by
Stephen Brawner (brawner@gmail.com)
     Commit Version: 1.6.0-4-g7f85cfe  Build Version: 1.6.7995.38578
     For more information, please see http://wiki.ros.org/sw_urdf_exporter -->
<robot name="plane_part">
    <transmission name="trans01">
        <type>transmission_interface/SimpleTransmission</type>
        <joint name="platform_x_joint">
            <hardwareInterface>hardware_interface/PositionJointInterface</hardwareInterface>
        </joint>
        <actuator name="motor01">
            <mechanicalReduction>1</mechanicalReduction>
            <hardwareInterface>hardware_interface/EffortJointInterface</hardwareInterface>
        </actuator>
    </transmission>
    <transmission name="trans02">
        <type>transmission_interface/SimpleTransmission</type>
        <joint name="platform_y_joint">
            <hardwareInterface>hardware_interface/PositionJointInterface</hardwareInterface>
        </joint>
        <actuator name="motor02">
            <mechanicalReduction>1</mechanicalReduction>
            <hardwareInterface>hardware_interface/EffortJointInterface</hardwareInterface>
        </actuator>
    </transmission>
    <transmission name="trans03">
        <type>transmission_interface/SimpleTransmission</type>
        <joint name="platform_z_joint">
            <hardwareInterface>hardware_interface/PositionJointInterface</hardwareInterface>
        </joint>
        <actuator name="motor03">
            <mechanicalReduction>1</mechanicalReduction>
            <hardwareInterface>hardware_interface/EffortJointInterface</hardwareInterface>
        </actuator>
    </transmission>
    <transmission name="trans04">
        <type>transmission_interface/SimpleTransmission</type>
        <joint name="platform_a_joint">
            <hardwareInterface>hardware_interface/PositionJointInterface</hardwareInterface>
        </joint>
        <actuator name="motor04">
            <mechanicalReduction>1</mechanicalReduction>
            <hardwareInterface>hardware_interface/EffortJointInterface</hardwareInterface>
        </actuator>
    </transmission>
    <transmission name="trans05">
        <type>transmission_interface/SimpleTransmission</type>
        <joint name="platform_b_joint">
            <hardwareInterface>hardware_interface/PositionJointInterface</hardwareInterface>
        </joint>
        <actuator name="motor05">
            <mechanicalReduction>1</mechanicalReduction>
            <hardwareInterface>hardware_interface/EffortJointInterface</hardwareInterface>
        </actuator>
    </transmission>
    <transmission name="trans06">
        <type>transmission_interface/SimpleTransmission</type>
        <joint name="platform_c_Joint">
            <hardwareInterface>hardware_interface/PositionJointInterface</hardwareInterface>
        </joint>
        <actuator name="motor06">
            <mechanicalReduction>1</mechanicalReduction>
            <hardwareInterface>hardware_interface/EffortJointInterface</hardwareInterface>
        </actuator>
    </transmission>
    <!--transmission
    name="refer01">
        <type>transmission_interface/SimpleTransmission</type>
        <joint name="reference_Joint">
            <hardwareInterface>hardware_interface/PositionJointInterface</hardwareInterface>
        </joint>
        <actuator name="mesure01">
            <mechanicalReduction>1</mechanicalReduction>
        </actuator>
    </transmission-->
    <!--transmission
    name="trans04_3">
        <type>transmission_interface/SimpleTransmission</type>
        <joint name="clap_roll_joint">
            <hardwareInterface>hardware_interface/PositionJointInterface</hardwareInterface>
        </joint>
        <actuator name="motor04_3">
            <mechanicalReduction>1</mechanicalReduction>
        </actuator>
    </transmission-->
    <gazebo reference="base_link">
        <material>Gazebo/Orange</material>
        <plugin name="gazebo_ros_control">
            <robotNamespace>/</robotNamespace>
        </plugin>
    </gazebo>
    <gazebo reference="bottom_Link">
        <material>Gazebo/Red</material>
    </gazebo>
    <gazebo reference="platform_Link">
        <material>Gazebo/Blue</material>
    </gazebo>
    <gazebo reference="reference_Link">
        <material>Gazebo/Black</material>
    </gazebo>
    <!--ros
    control plugin-->
    <gazebo>
        <plugin filename="libgazebo_ros_control.so" name="gazebo_ros_control">
            <robotNamespace>/</robotNamespace>
            <robotParam>/robot_description</robotParam>
            <robotSimType>gazebo_ros_control/DefaultRobotHWSim</robotSimType>
        </plugin>
    </gazebo>
    <material name="black">
        <color rgba="0.0 0.0 0.0 1.0" />
    </material>
    <material name="blue">
        <color rgba="0.0 0.0 0.8 1.0" />
    </material>
    <material name="green">
        <color rgba="0.0 0.8 0.0 1.0" />
    </material>
    <material name="grey">
        <color rgba="0.2 0.2 0.2 1.0" />
    </material>
    <material name="orange">
        <color rgba="1.0 0.4235294117647059 0.0392156862745098 1.0" />
    </material>
    <material name="brown">
        <color rgba="0.8705882352941177 0.8117647058823529 0.7647058823529411 1.0" />
    </material>
    <material name="red">
        <color rgba="0.8 0.0 0.0 1.0" />
    </material>
    <material name="white">
        <color rgba="1.0 1.0 1.0 1.0" />
    </material>
    <material name="yellow">
        <color rgba="1.0 1.0 0.0 1.0" />
    </material>
    <material name="chocolate">
        <color rgba="0.8235294117647058 0.4117647058823529 0.11764705882352941 1.0" />
    </material>
    <material name="purple">
        <color rgba="0.5019607843137255 0.0 0.5019607843137255 1.0" />
    </material>
    <link name="world" />
    <link name="base_link">
        <inertial>
            <origin rpy="0 0 0" xyz="0.00014734 -0.0013249 -0.027719" />
            <mass value="0.90493" />
            <inertia ixx="0.0011428" ixy="-1.8056E-35" ixz="-1.8016E-20" iyy="0.0011428"
                iyz="1.7948E-20" izz="0.00050332" />
        </inertial>
        <visual>
            <origin rpy="0 0 0" xyz="0 0 0" />
            <geometry>
                <mesh filename="package://plane_part/meshes/base_link.STL" />
            </geometry>
            <material name="">
                <color rgba="1 0 0 1" />
            </material>
        </visual>
        <collision>
            <origin rpy="0 0 0" xyz="0 0 0" />
            <geometry>
                <mesh filename="package://plane_part/meshes/base_link.STL" />
            </geometry>
        </collision>
    </link>
    <joint name="world_base" type="fixed">
        <origin rpy="0.0 0.0 0.0" xyz="0.0 0.0 0.2" />
        <parent link="world" />
        <child link="base_link" />
    </joint>
    <link name="bottom_Link">
        <inertial>
            <origin rpy="0 0 0" xyz="0.071702 1.7942E-05 0.0058498" />
            <mass value="91.018" />
            <inertia ixx="6.4041" ixy="-5.4882E-05" ixz="-3.6045E-06" iyy="6.3339" iyz="-1.8817E-05"
                izz="12.526" />
        </inertial>
        <visual>
            <origin rpy="0 0 0" xyz="0 0 0" />
            <geometry>
                <mesh filename="package://plane_part/meshes/bottom_Link.STL" />
            </geometry>
            <material name="">
                <color rgba="0 1 0 1" />
            </material>
        </visual>
        <collision>
            <origin rpy="0 0 0" xyz="0 0 0" />
            <geometry>
                <mesh filename="package://plane_part/meshes/bottom_Link.STL" />
            </geometry>
        </collision>
    </link>
    <joint name="bottom_joint" type="fixed">
        <origin rpy="0 0 0" xyz="0 0 0" />
        <parent link="base_link" />
        <child link="bottom_Link" />
        <axis xyz="1 0 0" />
    </joint>
    <link name="platform_x_Link">
        <inertial>
            <origin rpy="0.0 0.0 0.0" xyz="0.0 0.0 0.0" />
            <mass value="1" />
            <inertia ixx="1" ixy="0.0" ixz="0.0" iyy="1" iyz="0.0" izz="1" />
        </inertial>
    </link>
    <joint name="platform_x_joint" type="prismatic">
        <origin rpy="0 0 0" xyz="0 0 0.61449" />
        <parent link="bottom_Link" />
        <child link="platform_x_Link" />
        <axis xyz="1 0 0" />
        <limit effort="10000.0" lower="-0.3" upper="0.3" velocity="0.1" />
    </joint>
    <link name="platform_y_Link">
        <inertial>
            <origin rpy="0.0 0.0 0.0" xyz="0.0 0.0 0.0" />
            <mass value="1" />
            <inertia ixx="1" ixy="0.0" ixz="0.0" iyy="1" iyz="0.0" izz="1" />
        </inertial>
    </link>
    <joint name="platform_y_joint" type="prismatic">
        <origin rpy="0 0 0" xyz="0 0 0" />
        <parent link="platform_x_Link" />
        <child link="platform_y_Link" />
        <axis xyz="0 1 0" />
        <limit effort="10000.0" lower="-0.3" upper="0.3" velocity="0.1" />
    </joint>
    <link name="platform_z_Link">
        <inertial>
            <origin rpy="0.0 0.0 0.0" xyz="0.0 0.0 0.0" />
            <mass value="1" />
            <inertia ixx="1" ixy="0.0" ixz="0.0" iyy="1" iyz="0.0" izz="1" />
        </inertial>
    </link>
    <joint name="platform_z_joint" type="prismatic">
        <origin rpy="0 0 0" xyz="0 0 0" />
        <parent link="platform_y_Link" />
        <child link="platform_z_Link" />
        <axis xyz="0 0 1" />
        <limit effort="10000.0" lower="-0.3" upper="0.3" velocity="0.1" />
    </joint>
    <link name="platform_a_Link">
        <inertial>
            <origin rpy="0.0 0.0 0.0" xyz="0.0 0.0 0.0" />
            <mass value="1" />
            <inertia ixx="1" ixy="0.0" ixz="0.0" iyy="1" iyz="0.0" izz="1" />
        </inertial>
    </link>
    <joint name="platform_a_joint" type="revolute">
        <origin rpy="0 0 0" xyz="0 0 0" />
        <parent link="platform_z_Link" />
        <child link="platform_a_Link" />
        <axis xyz="1 0 0" />
        <limit effort="10000.0" lower="-0.3" upper="0.3" velocity="0.1" />
    </joint>
    <link name="platform_b_Link">
        <inertial>
            <origin rpy="0.0 0.0 0.0" xyz="0.0 0.0 0.0" />
            <mass value="1" />
            <inertia ixx="1" ixy="0.0" ixz="0.0" iyy="1" iyz="0.0" izz="1" />
        </inertial>
    </link>
    <joint name="platform_b_joint" type="revolute">
        <origin rpy="0 0 0" xyz="0 0 0" />
        <parent link="platform_a_Link" />
        <child link="platform_b_Link" />
        <axis xyz="0 1 0" />
        <limit effort="10000.0" lower="-0.3" upper="0.3" velocity="0.1" />
    </joint>
    <link name="platform_Link">
        <inertial>
            <origin rpy="0 0 0" xyz="0.0016018 0.0014397 -0.0097437" />
            <mass value="4.3742" />
            <inertia ixx="0.095075" ixy="-2.0348E-11" ixz="6.0005E-11" iyy="0.094958"
                iyz="1.164E-11" izz="0.18974" />
        </inertial>
        <visual>
            <origin rpy="0 0 0" xyz="0 0 0" />
            <geometry>
                <mesh filename="package://plane_part/meshes/platform_Link.STL" />
            </geometry>
            <material name="">
                <color rgba="0 0 1 1" />
            </material>
        </visual>
        <collision>
            <origin rpy="0 0 0" xyz="0 0 0" />
            <geometry>
                <mesh filename="package://plane_part/meshes/platform_Link.STL" />
            </geometry>
        </collision>
    </link>
    <joint name="platform_c_Joint" type="revolute">
        <origin rpy="0 0 0" xyz="0 0 0" />
        <parent link="platform_b_Link" />
        <child link="platform_Link" />
        <axis xyz="0 0 1" />
        <limit effort="10000.0" lower="-0.3" upper="0.3" velocity="0.1" />
    </joint>
    <link name="modulating_Link">
        <inertial>
            <origin rpy="0 0 0" xyz="0.46708 -6.9672E-07 -0.18298" />
            <mass value="11.25" />
            <inertia ixx="0.40589" ixy="1.2212E-15" ixz="1.6631E-13" iyy="0.28426" iyz="1.2524E-15"
                izz="0.50773" />
        </inertial>
        <visual>
            <origin rpy="0 0 0" xyz="0 0 0" />
            <geometry>
                <mesh filename="package://plane_part/meshes/modulating_Link.STL" />
            </geometry>
            <material name="">
                <color rgba="1 1 0 1" />
            </material>
        </visual>
        <collision>
            <origin rpy="0 0 0" xyz="0 0 0" />
            <geometry>
                <mesh filename="package://plane_part/meshes/modulating_Link.STL" />
            </geometry>
        </collision>
    </link>
    <joint name="modulating_Joint" type="fixed">
        <origin rpy="0 0 0" xyz="-0.236 0 0.56" />
        <parent link="platform_Link" />
        <child link="modulating_Link" />
        <axis xyz="1 0 0" />
    </joint>
    <link name="reference_Link">
        <inertial>
            <origin rpy="0 0 0" xyz="-0.36224 -7.2789E-07 -0.21599" />
            <mass value="10.768" />
            <inertia ixx="0.43054" ixy="-4.8572E-17" ixz="3.0383E-17" iyy="0.17237" iyz="2.6573E-17"
                izz="0.51657" />
        </inertial>
        <visual>
            <origin rpy="0 0 0" xyz="0 0 0" />
            <geometry>
                <mesh filename="package://plane_part/meshes/reference_Link.STL" />
            </geometry>
            <material name="">
                <color rgba="0 1 1 1" />
            </material>
        </visual>
        <collision>
            <origin rpy="0 0 0" xyz="0 0 0" />
            <geometry>
                <mesh filename="package://plane_part/meshes/reference_Link.STL" />
            </geometry>
        </collision>
    </link>
    <joint name="reference_Joint" type="fixed">
        <origin rpy="0 0 0" xyz="1.4503 0 1.1964" />
        <parent link="bottom_Link" />
        <child link="reference_Link" />
        <axis xyz="1 0 0" />
    </joint>
</robot>